<?xml version="1.0"?>

<robot xmlns:xacro="http://www.ros.org/wiki/xacro" >

<xacro:macro name="wheel" params="prefix reflect">

    <joint name="${prefix}_wheel_joint" type="continuous">
        <parent link="base_link"/>
        <child link="${prefix}_wheel"/>
        <origin xyz="0 ${diff_wheel_y * reflect} 0" rpy="${-pi/2 * reflect} 0 0"/>
        <axis xyz="0 0 ${reflect}"/>
    </joint>

    <link name="${prefix}_wheel">
    <visual>
        <geometry>
            <cylinder length="${diff_wheel_width}" radius="${diff_wheel_radius}" />
        </geometry>
        <material name="blue"/>
    </visual>

    <xacro:inertial_cylinder mass="0.1" length="0.05" radius="0.05">
        <origin xyz="0 0 0" rpy="0 0 0"/>
    </xacro:inertial_cylinder>

    </link>

    <gazebo reference="chassis">
        <material>Gazebo/Blue</material>
    </gazebo>   
</xacro:macro>

</robot>